2024-10-20 11:13:23,688 - app.utils - INFO - Correo de restablecimiento de contraseña enviado a edfrutos@gmail.com [in /home/ec2-user/aws_edfcatalogoqr/app/utils.py:164]
2024-10-21 08:55:43,957 - app - INFO - Aplicación Flask iniciada correctamente [in /home/ec2-user/aws_edfcatalogoqr/app/__init__.py:70]
2024-10-21 08:55:44,293 - app.models - INFO - Desconexión exitosa de la base de datos anterior. [in /home/ec2-user/aws_edfcatalogoqr/app/models.py:23]
2024-10-21 08:55:44,327 - app.models - INFO - Conectado a la base de datos. [in /home/ec2-user/aws_edfcatalogoqr/app/models.py:29]
2024-10-21 08:56:32,988 - app - ERROR - Exception on /containers [GET] [in /home/ec2-user/.local/lib/python3.9/site-packages/flask/app.py:1457]
Traceback (most recent call last):
  File "/home/ec2-user/.local/lib/python3.9/site-packages/flask/app.py", line 2073, in wsgi_app
    response = self.full_dispatch_request()
  File "/home/ec2-user/.local/lib/python3.9/site-packages/flask/app.py", line 1518, in full_dispatch_request
    rv = self.handle_user_exception(e)
  File "/home/ec2-user/.local/lib/python3.9/site-packages/flask/app.py", line 1516, in full_dispatch_request
    rv = self.dispatch_request()
  File "/home/ec2-user/.local/lib/python3.9/site-packages/flask/app.py", line 1502, in dispatch_request
    return self.ensure_sync(self.view_functions[rule.endpoint])(**req.view_args)
  File "/home/ec2-user/.local/lib/python3.9/site-packages/flask_login/utils.py", line 290, in decorated_view
    return current_app.ensure_sync(func)(*args, **kwargs)
  File "/home/ec2-user/aws_edfcatalogoqr/app/routes.py", line 324, in list_containers
    return render_template('list_containers.html', title='Mis Contenedores', containers=containers, form=form)
  File "/home/ec2-user/.local/lib/python3.9/site-packages/flask/templating.py", line 147, in render_template
    return _render(
  File "/home/ec2-user/.local/lib/python3.9/site-packages/flask/templating.py", line 128, in _render
    rv = template.render(context)
  File "/home/ec2-user/.local/lib/python3.9/site-packages/jinja2/environment.py", line 1304, in render
    self.environment.handle_exception()
  File "/home/ec2-user/.local/lib/python3.9/site-packages/jinja2/environment.py", line 939, in handle_exception
    raise rewrite_traceback_stack(source=source)
  File "/home/ec2-user/aws_edfcatalogoqr/app/templates/list_containers.html", line 1, in top-level template code
    {% extends "layout.html" %}
  File "/home/ec2-user/aws_edfcatalogoqr/app/templates/layout.html", line 141, in top-level template code
    {% block content %}{% endblock %}
  File "/home/ec2-user/aws_edfcatalogoqr/app/templates/list_containers.html", line 28, in block 'content'
    <a href="{{ url_for('main.edit_container', container_id=container.id) }}" class="btn btn-warning">Editar</a>
  File "/home/ec2-user/.local/lib/python3.9/site-packages/flask/helpers.py", line 338, in url_for
    return appctx.app.handle_url_build_error(error, endpoint, values)
  File "/home/ec2-user/.local/lib/python3.9/site-packages/flask/helpers.py", line 325, in url_for
    rv = url_adapter.build(
  File "/home/ec2-user/.local/lib/python3.9/site-packages/werkzeug/routing.py", line 2315, in build
    raise BuildError(endpoint, values, method, self)
werkzeug.routing.BuildError: Could not build url for endpoint 'main.edit_container' with values ['container_id']. Did you mean 'main.print_container' instead?
2024-10-21 09:05:26,412 - app - INFO - Aplicación Flask iniciada correctamente [in /home/ec2-user/aws_edfcatalogoqr/app/__init__.py:70]
2024-10-21 09:05:26,502 - app.models - INFO - Desconexión exitosa de la base de datos anterior. [in /home/ec2-user/aws_edfcatalogoqr/app/models.py:23]
2024-10-21 09:05:26,536 - app.models - INFO - Conectado a la base de datos. [in /home/ec2-user/aws_edfcatalogoqr/app/models.py:29]
2024-10-21 09:05:38,088 - app - ERROR - Exception on /containers [GET] [in /home/ec2-user/.local/lib/python3.9/site-packages/flask/app.py:1457]
Traceback (most recent call last):
  File "/home/ec2-user/.local/lib/python3.9/site-packages/flask/app.py", line 2073, in wsgi_app
    response = self.full_dispatch_request()
  File "/home/ec2-user/.local/lib/python3.9/site-packages/flask/app.py", line 1518, in full_dispatch_request
    rv = self.handle_user_exception(e)
  File "/home/ec2-user/.local/lib/python3.9/site-packages/flask/app.py", line 1516, in full_dispatch_request
    rv = self.dispatch_request()
  File "/home/ec2-user/.local/lib/python3.9/site-packages/flask/app.py", line 1502, in dispatch_request
    return self.ensure_sync(self.view_functions[rule.endpoint])(**req.view_args)
  File "/home/ec2-user/.local/lib/python3.9/site-packages/flask_login/utils.py", line 290, in decorated_view
    return current_app.ensure_sync(func)(*args, **kwargs)
  File "/home/ec2-user/aws_edfcatalogoqr/app/routes.py", line 324, in list_containers
    return render_template('list_containers.html', title='Mis Contenedores', containers=containers, form=form)
  File "/home/ec2-user/.local/lib/python3.9/site-packages/flask/templating.py", line 147, in render_template
    return _render(
  File "/home/ec2-user/.local/lib/python3.9/site-packages/flask/templating.py", line 128, in _render
    rv = template.render(context)
  File "/home/ec2-user/.local/lib/python3.9/site-packages/jinja2/environment.py", line 1304, in render
    self.environment.handle_exception()
  File "/home/ec2-user/.local/lib/python3.9/site-packages/jinja2/environment.py", line 939, in handle_exception
    raise rewrite_traceback_stack(source=source)
  File "/home/ec2-user/aws_edfcatalogoqr/app/templates/list_containers.html", line 1, in top-level template code
    {% extends "layout.html" %}
  File "/home/ec2-user/aws_edfcatalogoqr/app/templates/layout.html", line 141, in top-level template code
    {% block content %}{% endblock %}
  File "/home/ec2-user/aws_edfcatalogoqr/app/templates/list_containers.html", line 28, in block 'content'
    <a href="{{ url_for('main.edit_container', container_id=container.id) }}" class="btn btn-warning">Editar</a>
  File "/home/ec2-user/.local/lib/python3.9/site-packages/flask/helpers.py", line 338, in url_for
    return appctx.app.handle_url_build_error(error, endpoint, values)
  File "/home/ec2-user/.local/lib/python3.9/site-packages/flask/helpers.py", line 325, in url_for
    rv = url_adapter.build(
  File "/home/ec2-user/.local/lib/python3.9/site-packages/werkzeug/routing.py", line 2315, in build
    raise BuildError(endpoint, values, method, self)
werkzeug.routing.BuildError: Could not build url for endpoint 'main.edit_container' with values ['container_id']. Did you mean 'main.print_container' instead?
2024-10-21 09:06:22,823 - app - INFO - Aplicación Flask iniciada correctamente [in /home/ec2-user/aws_edfcatalogoqr/app/__init__.py:70]
2024-10-21 09:06:22,908 - app.models - INFO - Desconexión exitosa de la base de datos anterior. [in /home/ec2-user/aws_edfcatalogoqr/app/models.py:23]
2024-10-21 09:06:22,982 - app.models - INFO - Conectado a la base de datos. [in /home/ec2-user/aws_edfcatalogoqr/app/models.py:29]
2024-10-21 09:06:36,434 - app - ERROR - Exception on /containers [GET] [in /home/ec2-user/.local/lib/python3.9/site-packages/flask/app.py:1457]
Traceback (most recent call last):
  File "/home/ec2-user/.local/lib/python3.9/site-packages/flask/app.py", line 2073, in wsgi_app
    response = self.full_dispatch_request()
  File "/home/ec2-user/.local/lib/python3.9/site-packages/flask/app.py", line 1518, in full_dispatch_request
    rv = self.handle_user_exception(e)
  File "/home/ec2-user/.local/lib/python3.9/site-packages/flask/app.py", line 1516, in full_dispatch_request
    rv = self.dispatch_request()
  File "/home/ec2-user/.local/lib/python3.9/site-packages/flask/app.py", line 1502, in dispatch_request
    return self.ensure_sync(self.view_functions[rule.endpoint])(**req.view_args)
  File "/home/ec2-user/.local/lib/python3.9/site-packages/flask_login/utils.py", line 290, in decorated_view
    return current_app.ensure_sync(func)(*args, **kwargs)
  File "/home/ec2-user/aws_edfcatalogoqr/app/routes.py", line 324, in list_containers
    return render_template('list_containers.html', title='Mis Contenedores', containers=containers, form=form)
  File "/home/ec2-user/.local/lib/python3.9/site-packages/flask/templating.py", line 147, in render_template
    return _render(
  File "/home/ec2-user/.local/lib/python3.9/site-packages/flask/templating.py", line 128, in _render
    rv = template.render(context)
  File "/home/ec2-user/.local/lib/python3.9/site-packages/jinja2/environment.py", line 1304, in render
    self.environment.handle_exception()
  File "/home/ec2-user/.local/lib/python3.9/site-packages/jinja2/environment.py", line 939, in handle_exception
    raise rewrite_traceback_stack(source=source)
  File "/home/ec2-user/aws_edfcatalogoqr/app/templates/list_containers.html", line 1, in top-level template code
    {% extends "layout.html" %}
  File "/home/ec2-user/aws_edfcatalogoqr/app/templates/layout.html", line 141, in top-level template code
    {% block content %}{% endblock %}
  File "/home/ec2-user/aws_edfcatalogoqr/app/templates/list_containers.html", line 28, in block 'content'
    <a href="{{ url_for('main.edit_container', container_id=container.id) }}" class="btn btn-warning">Editar</a>
  File "/home/ec2-user/.local/lib/python3.9/site-packages/flask/helpers.py", line 338, in url_for
    return appctx.app.handle_url_build_error(error, endpoint, values)
  File "/home/ec2-user/.local/lib/python3.9/site-packages/flask/helpers.py", line 325, in url_for
    rv = url_adapter.build(
  File "/home/ec2-user/.local/lib/python3.9/site-packages/werkzeug/routing.py", line 2315, in build
    raise BuildError(endpoint, values, method, self)
werkzeug.routing.BuildError: Could not build url for endpoint 'main.edit_container' with values ['container_id']. Did you mean 'main.print_container' instead?
