2024-09-10 17:41:45,585 - app - ERROR - Exception on /about [GET] [in /home/ec2-user/.local/lib/python3.9/site-packages/flask/app.py:1457]
Traceback (most recent call last):
  File "/home/ec2-user/.local/lib/python3.9/site-packages/flask/app.py", line 2073, in wsgi_app
    response = self.full_dispatch_request()
  File "/home/ec2-user/.local/lib/python3.9/site-packages/flask/app.py", line 1518, in full_dispatch_request
    rv = self.handle_user_exception(e)
  File "/home/ec2-user/.local/lib/python3.9/site-packages/flask/app.py", line 1516, in full_dispatch_request
    rv = self.dispatch_request()
  File "/home/ec2-user/.local/lib/python3.9/site-packages/flask/app.py", line 1502, in dispatch_request
    return self.ensure_sync(self.view_functions[rule.endpoint])(**req.view_args)
  File "/home/ec2-user/aws_edfcatalogoqr/app/routes.py", line 60, in about
    return render_template('about.html', title='Acerca de')
  File "/home/ec2-user/.local/lib/python3.9/site-packages/flask/templating.py", line 148, in render_template
    ctx.app.jinja_env.get_or_select_template(template_name_or_list),
  File "/home/ec2-user/.local/lib/python3.9/site-packages/jinja2/environment.py", line 1084, in get_or_select_template
    return self.get_template(template_name_or_list, parent, globals)
  File "/home/ec2-user/.local/lib/python3.9/site-packages/jinja2/environment.py", line 1013, in get_template
    return self._load_template(name, globals)
  File "/home/ec2-user/.local/lib/python3.9/site-packages/jinja2/environment.py", line 972, in _load_template
    template = self.loader.load(self, name, self.make_globals(globals))
  File "/home/ec2-user/.local/lib/python3.9/site-packages/jinja2/loaders.py", line 138, in load
    code = environment.compile(source, name, filename)
  File "/home/ec2-user/.local/lib/python3.9/site-packages/jinja2/environment.py", line 768, in compile
    self.handle_exception(source=source_hint)
  File "/home/ec2-user/.local/lib/python3.9/site-packages/jinja2/environment.py", line 939, in handle_exception
    raise rewrite_traceback_stack(source=source)
  File "/home/ec2-user/aws_edfcatalogoqr/app/templates/about.html", line 22, in template
    {% endif %}
jinja2.exceptions.TemplateSyntaxError: Encountered unknown tag 'endif'. Jinja was looking for the following tags: 'endblock'. The innermost block that needs to be closed is 'block'.
2024-09-10 17:43:58,004 - app - INFO - Aplicación Flask iniciada correctamente [in /home/ec2-user/aws_edfcatalogoqr/app/__init__.py:70]
2024-09-10 17:43:58,085 - app.models - INFO - Desconexión exitosa de la base de datos anterior. [in /home/ec2-user/aws_edfcatalogoqr/app/models.py:26]
2024-09-10 17:43:58,124 - app.models - INFO - Conectado a la base de datos. [in /home/ec2-user/aws_edfcatalogoqr/app/models.py:33]
2024-09-10 17:48:35,562 - app - INFO - Aplicación Flask iniciada correctamente [in /home/ec2-user/aws_edfcatalogoqr/app/__init__.py:70]
2024-09-10 17:48:35,641 - app.models - INFO - Desconexión exitosa de la base de datos anterior. [in /home/ec2-user/aws_edfcatalogoqr/app/models.py:26]
2024-09-10 17:48:35,680 - app.models - INFO - Conectado a la base de datos. [in /home/ec2-user/aws_edfcatalogoqr/app/models.py:33]
2024-09-10 17:51:03,375 - app - INFO - Aplicación Flask iniciada correctamente [in /home/ec2-user/aws_edfcatalogoqr/app/__init__.py:70]
2024-09-10 17:51:03,455 - app.models - INFO - Desconexión exitosa de la base de datos anterior. [in /home/ec2-user/aws_edfcatalogoqr/app/models.py:26]
2024-09-10 17:51:03,492 - app.models - INFO - Conectado a la base de datos. [in /home/ec2-user/aws_edfcatalogoqr/app/models.py:33]
2024-09-10 18:06:47,160 - app - INFO - Aplicación Flask iniciada correctamente [in /home/ec2-user/aws_edfcatalogoqr/app/__init__.py:70]
2024-09-10 18:06:47,239 - app.models - INFO - Desconexión exitosa de la base de datos anterior. [in /home/ec2-user/aws_edfcatalogoqr/app/models.py:26]
2024-09-10 18:06:47,275 - app.models - INFO - Conectado a la base de datos. [in /home/ec2-user/aws_edfcatalogoqr/app/models.py:33]
2024-09-10 18:14:08,670 - app - INFO - Aplicación Flask iniciada correctamente [in /home/ec2-user/aws_edfcatalogoqr/app/__init__.py:70]
2024-09-10 18:14:08,749 - app.models - INFO - Desconexión exitosa de la base de datos anterior. [in /home/ec2-user/aws_edfcatalogoqr/app/models.py:26]
2024-09-10 18:14:08,786 - app.models - INFO - Conectado a la base de datos. [in /home/ec2-user/aws_edfcatalogoqr/app/models.py:33]
2024-09-10 18:14:56,694 - app - INFO - Aplicación Flask iniciada correctamente [in /home/ec2-user/aws_edfcatalogoqr/app/__init__.py:70]
2024-09-10 18:14:56,774 - app.models - INFO - Desconexión exitosa de la base de datos anterior. [in /home/ec2-user/aws_edfcatalogoqr/app/models.py:26]
2024-09-10 18:14:56,812 - app.models - INFO - Conectado a la base de datos. [in /home/ec2-user/aws_edfcatalogoqr/app/models.py:33]
2024-09-10 18:15:29,854 - app - INFO - Aplicación Flask iniciada correctamente [in /home/ec2-user/aws_edfcatalogoqr/app/__init__.py:70]
2024-09-10 18:15:29,934 - app.models - INFO - Desconexión exitosa de la base de datos anterior. [in /home/ec2-user/aws_edfcatalogoqr/app/models.py:26]
2024-09-10 18:15:29,972 - app.models - INFO - Conectado a la base de datos. [in /home/ec2-user/aws_edfcatalogoqr/app/models.py:33]
2024-09-10 18:22:08,375 - app - INFO - Aplicación Flask iniciada correctamente [in /home/ec2-user/aws_edfcatalogoqr/app/__init__.py:70]
2024-09-10 18:22:08,457 - app.models - INFO - Desconexión exitosa de la base de datos anterior. [in /home/ec2-user/aws_edfcatalogoqr/app/models.py:26]
2024-09-10 18:22:08,495 - app.models - INFO - Conectado a la base de datos. [in /home/ec2-user/aws_edfcatalogoqr/app/models.py:33]
2024-09-10 18:22:47,593 - app - INFO - Cargando datos del usuario: edefrutos [in /home/ec2-user/aws_edfcatalogoqr/app/routes.py:156]
2024-09-10 18:22:47,593 - app - INFO - Mostrando imagen de perfil para el usuario edefrutos: 87371de9a20d1e8d.jpeg [in /home/ec2-user/aws_edfcatalogoqr/app/routes.py:166]
2024-09-10 20:54:32,754 - app - INFO - Cargando datos del usuario: edefrutos [in /home/ec2-user/aws_edfcatalogoqr/app/routes.py:156]
2024-09-10 20:54:32,755 - app - INFO - Mostrando imagen de perfil para el usuario edefrutos: 87371de9a20d1e8d.jpeg [in /home/ec2-user/aws_edfcatalogoqr/app/routes.py:166]
2024-09-10 20:55:17,859 - app - ERROR - Exception on /reset_password [POST] [in /home/ec2-user/.local/lib/python3.9/site-packages/flask/app.py:1457]
Traceback (most recent call last):
  File "/home/ec2-user/.local/lib/python3.9/site-packages/flask/app.py", line 2073, in wsgi_app
    response = self.full_dispatch_request()
  File "/home/ec2-user/.local/lib/python3.9/site-packages/flask/app.py", line 1518, in full_dispatch_request
    rv = self.handle_user_exception(e)
  File "/home/ec2-user/.local/lib/python3.9/site-packages/flask/app.py", line 1516, in full_dispatch_request
    rv = self.dispatch_request()
  File "/home/ec2-user/.local/lib/python3.9/site-packages/flask/app.py", line 1502, in dispatch_request
    return self.ensure_sync(self.view_functions[rule.endpoint])(**req.view_args)
  File "/home/ec2-user/aws_edfcatalogoqr/app/routes.py", line 178, in reset_request
    send_reset_email(user)
  File "/home/ec2-user/aws_edfcatalogoqr/app/utils.py", line 148, in send_reset_email
    {url_for('main.reset_token', token=token, _external=True)}
  File "/home/ec2-user/.local/lib/python3.9/site-packages/flask/helpers.py", line 338, in url_for
    return appctx.app.handle_url_build_error(error, endpoint, values)
  File "/home/ec2-user/.local/lib/python3.9/site-packages/flask/helpers.py", line 325, in url_for
    rv = url_adapter.build(
  File "/home/ec2-user/.local/lib/python3.9/site-packages/werkzeug/routing.py", line 2315, in build
    raise BuildError(endpoint, values, method, self)
werkzeug.routing.BuildError: Could not build url for endpoint 'main.reset_token' with values ['token']. Did you mean 'main.reset_request' instead?
2024-09-11 08:51:56,800 - app - INFO - Aplicación Flask iniciada correctamente [in /home/ec2-user/aws_edfcatalogoqr/app/__init__.py:70]
2024-09-11 08:51:56,879 - app.models - INFO - Desconexión exitosa de la base de datos anterior. [in /home/ec2-user/aws_edfcatalogoqr/app/models.py:26]
2024-09-11 08:51:56,932 - app.models - INFO - Conectado a la base de datos. [in /home/ec2-user/aws_edfcatalogoqr/app/models.py:33]
2024-09-11 08:53:12,669 - app - INFO - Aplicación Flask iniciada correctamente [in /home/ec2-user/aws_edfcatalogoqr/app/__init__.py:70]
2024-09-11 08:53:12,749 - app.models - INFO - Desconexión exitosa de la base de datos anterior. [in /home/ec2-user/aws_edfcatalogoqr/app/models.py:26]
2024-09-11 08:53:12,788 - app.models - INFO - Conectado a la base de datos. [in /home/ec2-user/aws_edfcatalogoqr/app/models.py:33]
2024-09-11 09:40:12,590 - app - INFO - Aplicación Flask iniciada correctamente [in /home/ec2-user/aws_edfcatalogoqr/app/__init__.py:70]
2024-09-11 09:40:12,670 - app.models - INFO - Desconexión exitosa de la base de datos anterior. [in /home/ec2-user/aws_edfcatalogoqr/app/models.py:26]
2024-09-11 09:40:12,711 - app.models - INFO - Conectado a la base de datos. [in /home/ec2-user/aws_edfcatalogoqr/app/models.py:33]
2024-09-11 10:46:54,922 - app - INFO - Cargando datos del usuario: edefrutos [in /home/ec2-user/aws_edfcatalogoqr/app/routes.py:156]
2024-09-11 10:46:54,922 - app - INFO - Mostrando imagen de perfil para el usuario edefrutos: 87371de9a20d1e8d.jpeg [in /home/ec2-user/aws_edfcatalogoqr/app/routes.py:166]
2024-09-11 10:47:14,207 - app - INFO - Iniciando actualización de cuenta para el usuario: edefrutos [in /home/ec2-user/aws_edfcatalogoqr/app/routes.py:113]
2024-09-11 10:47:14,207 - app - INFO - Información recibida - Username: edefrutos, Email: edfrutos@gmail.com, Address: Calle Mango, 3, Phone: 983246972 [in /home/ec2-user/aws_edfcatalogoqr/app/routes.py:114]
2024-09-11 10:47:14,207 - app - INFO - Actualizando foto de perfil para el usuario: edefrutos [in /home/ec2-user/aws_edfcatalogoqr/app/routes.py:119]
